/home/rgundaka/miniconda3/envs/CPINO/lib/python3.10/site-packages/torch/functional.py:568: UserWarning: torch.meshgrid: in an upcoming release, it will be required to pass the indexing argument. (Triggered internally at  ../aten/src/ATen/native/TensorShape.cpp:2228.)
  return _VF.meshgrid(tensors, **kwargs)  # type: ignore[attr-defined]
wandb: Currently logged in as: rishigundakaram. Use `wandb login --relogin` to force relogin
wandb: WARNING Invalid value for property run_group: ['wave1D_PINO']. This will raise an error in the future.
loading data
data is loaded
using device: cuda:0
Traceback (most recent call last):
  File "/home/rgundaka/miniconda3/envs/CPINO/lib/python3.10/site-packages/wandb/sdk/wandb_init.py", line 999, in init
    run = wi.init()
  File "/home/rgundaka/miniconda3/envs/CPINO/lib/python3.10/site-packages/wandb/sdk/wandb_init.py", line 630, in init
    run_result = backend.interface.communicate_run(
  File "/home/rgundaka/miniconda3/envs/CPINO/lib/python3.10/site-packages/wandb/sdk/interface/interface.py", line 222, in communicate_run
    run = self._make_run(run_obj)
  File "/home/rgundaka/miniconda3/envs/CPINO/lib/python3.10/site-packages/wandb/sdk/interface/interface.py", line 172, in _make_run
    run._make_proto_run(proto_run)
  File "/home/rgundaka/miniconda3/envs/CPINO/lib/python3.10/site-packages/wandb/sdk/wandb_run.py", line 648, in _make_proto_run
    run.run_group = self._group
TypeError: ['wave1D_PINO'] has type list, but expected one of: bytes, unicode
Problem at: /groups/tensorlab/rgundaka/code/CPINO/run.py 72 <module>
wandb: ERROR Abnormal program exit
Traceback (most recent call last):
  File "/home/rgundaka/miniconda3/envs/CPINO/lib/python3.10/site-packages/wandb/sdk/wandb_init.py", line 999, in init
    run = wi.init()
  File "/home/rgundaka/miniconda3/envs/CPINO/lib/python3.10/site-packages/wandb/sdk/wandb_init.py", line 630, in init
    run_result = backend.interface.communicate_run(
  File "/home/rgundaka/miniconda3/envs/CPINO/lib/python3.10/site-packages/wandb/sdk/interface/interface.py", line 222, in communicate_run
    run = self._make_run(run_obj)
  File "/home/rgundaka/miniconda3/envs/CPINO/lib/python3.10/site-packages/wandb/sdk/interface/interface.py", line 172, in _make_run
    run._make_proto_run(proto_run)
  File "/home/rgundaka/miniconda3/envs/CPINO/lib/python3.10/site-packages/wandb/sdk/wandb_run.py", line 648, in _make_proto_run
    run.run_group = self._group
TypeError: ['wave1D_PINO'] has type list, but expected one of: bytes, unicode

The above exception was the direct cause of the following exception:

Traceback (most recent call last):
  File "/groups/tensorlab/rgundaka/code/CPINO/run.py", line 72, in <module>
    run = wandb.init(project=config['info']['project'],
  File "/home/rgundaka/miniconda3/envs/CPINO/lib/python3.10/site-packages/wandb/sdk/wandb_init.py", line 1037, in init
    raise Exception("problem") from error_seen
Exception: problem
srun: Job step aborted: Waiting up to 32 seconds for job step to finish.
slurmstepd: error: *** STEP 26223732.0 ON hpc-23-28 CANCELLED AT 2022-06-27T20:56:16 DUE TO TIME LIMIT ***
slurmstepd: error: *** JOB 26223732 ON hpc-23-28 CANCELLED AT 2022-06-27T20:56:16 DUE TO TIME LIMIT ***
